[2023-06-08T20:50:09.043+0000] {taskinstance.py:1103} INFO - Dependencies all met for dep_context=non-requeueable deps ti=<TaskInstance: dag_with_python_operator_v04.greet manual__2023-06-08T20:50:07.346232+00:00 [queued]>
[2023-06-08T20:50:09.048+0000] {taskinstance.py:1103} INFO - Dependencies all met for dep_context=requeueable deps ti=<TaskInstance: dag_with_python_operator_v04.greet manual__2023-06-08T20:50:07.346232+00:00 [queued]>
[2023-06-08T20:50:09.049+0000] {taskinstance.py:1308} INFO - Starting attempt 1 of 6
[2023-06-08T20:50:09.056+0000] {taskinstance.py:1327} INFO - Executing <Task(PythonOperator): greet> on 2023-06-08 20:50:07.346232+00:00
[2023-06-08T20:50:09.059+0000] {standard_task_runner.py:57} INFO - Started process 2691 to run task
[2023-06-08T20:50:09.062+0000] {standard_task_runner.py:84} INFO - Running: ['***', 'tasks', 'run', 'dag_with_python_operator_v04', 'greet', 'manual__2023-06-08T20:50:07.346232+00:00', '--job-id', '72', '--raw', '--subdir', 'DAGS_FOLDER/create_dag_with_python_operator.py', '--cfg-path', '/tmp/tmpqciivp6l']
[2023-06-08T20:50:09.064+0000] {standard_task_runner.py:85} INFO - Job 72: Subtask greet
[2023-06-08T20:50:09.097+0000] {task_command.py:410} INFO - Running <TaskInstance: dag_with_python_operator_v04.greet manual__2023-06-08T20:50:07.346232+00:00 [running]> on host e3f9b08eb2c7
[2023-06-08T20:50:09.151+0000] {taskinstance.py:1547} INFO - Exporting env vars: AIRFLOW_CTX_DAG_OWNER='znawawi' AIRFLOW_CTX_DAG_ID='dag_with_python_operator_v04' AIRFLOW_CTX_TASK_ID='greet' AIRFLOW_CTX_EXECUTION_DATE='2023-06-08T20:50:07.346232+00:00' AIRFLOW_CTX_TRY_NUMBER='1' AIRFLOW_CTX_DAG_RUN_ID='manual__2023-06-08T20:50:07.346232+00:00'
[2023-06-08T20:50:09.152+0000] {taskinstance.py:1824} ERROR - Task failed with exception
Traceback (most recent call last):
  File "/home/airflow/.local/lib/python3.7/site-packages/airflow/operators/python.py", line 181, in execute
    return_value = self.execute_callable()
  File "/home/airflow/.local/lib/python3.7/site-packages/airflow/operators/python.py", line 198, in execute_callable
    return self.python_callable(*self.op_args, **self.op_kwargs)
TypeError: greet() missing 1 required positional argument: 'age'
[2023-06-08T20:50:09.158+0000] {taskinstance.py:1350} INFO - Marking task as UP_FOR_RETRY. dag_id=dag_with_python_operator_v04, task_id=greet, execution_date=20230608T205007, start_date=20230608T205009, end_date=20230608T205009
[2023-06-08T20:50:09.164+0000] {standard_task_runner.py:109} ERROR - Failed to execute job 72 for task greet (greet() missing 1 required positional argument: 'age'; 2691)
[2023-06-08T20:50:09.194+0000] {local_task_job_runner.py:225} INFO - Task exited with return code 1
[2023-06-08T20:50:09.207+0000] {taskinstance.py:2651} INFO - 0 downstream tasks scheduled from follow-on schedule check
