[2023-06-08T20:35:24.151+0000] {taskinstance.py:1103} INFO - Dependencies all met for dep_context=non-requeueable deps ti=<TaskInstance: dag_with_python_operator_v04.greet scheduled__2023-06-07T00:00:00+00:00 [queued]>
[2023-06-08T20:35:24.156+0000] {taskinstance.py:1103} INFO - Dependencies all met for dep_context=requeueable deps ti=<TaskInstance: dag_with_python_operator_v04.greet scheduled__2023-06-07T00:00:00+00:00 [queued]>
[2023-06-08T20:35:24.157+0000] {taskinstance.py:1308} INFO - Starting attempt 1 of 6
[2023-06-08T20:35:24.164+0000] {taskinstance.py:1327} INFO - Executing <Task(PythonOperator): greet> on 2023-06-07 00:00:00+00:00
[2023-06-08T20:35:24.167+0000] {standard_task_runner.py:57} INFO - Started process 2146 to run task
[2023-06-08T20:35:24.170+0000] {standard_task_runner.py:84} INFO - Running: ['***', 'tasks', 'run', 'dag_with_python_operator_v04', 'greet', 'scheduled__2023-06-07T00:00:00+00:00', '--job-id', '62', '--raw', '--subdir', 'DAGS_FOLDER/create_dag_with_python_operator.py', '--cfg-path', '/tmp/tmp2oe4h4_3']
[2023-06-08T20:35:24.172+0000] {standard_task_runner.py:85} INFO - Job 62: Subtask greet
[2023-06-08T20:35:24.205+0000] {task_command.py:410} INFO - Running <TaskInstance: dag_with_python_operator_v04.greet scheduled__2023-06-07T00:00:00+00:00 [running]> on host e3f9b08eb2c7
[2023-06-08T20:35:24.254+0000] {taskinstance.py:1547} INFO - Exporting env vars: AIRFLOW_CTX_DAG_OWNER='znawawi' AIRFLOW_CTX_DAG_ID='dag_with_python_operator_v04' AIRFLOW_CTX_TASK_ID='greet' AIRFLOW_CTX_EXECUTION_DATE='2023-06-07T00:00:00+00:00' AIRFLOW_CTX_TRY_NUMBER='1' AIRFLOW_CTX_DAG_RUN_ID='scheduled__2023-06-07T00:00:00+00:00'
[2023-06-08T20:35:24.255+0000] {taskinstance.py:1824} ERROR - Task failed with exception
Traceback (most recent call last):
  File "/home/airflow/.local/lib/python3.7/site-packages/airflow/operators/python.py", line 181, in execute
    return_value = self.execute_callable()
  File "/home/airflow/.local/lib/python3.7/site-packages/airflow/operators/python.py", line 198, in execute_callable
    return self.python_callable(*self.op_args, **self.op_kwargs)
  File "/opt/airflow/dags/create_dag_with_python_operator.py", line 13, in greet
    name = ti.xcoms_pull(task_ids='get_name')
AttributeError: 'TaskInstance' object has no attribute 'xcoms_pull'
[2023-06-08T20:35:24.262+0000] {taskinstance.py:1350} INFO - Marking task as UP_FOR_RETRY. dag_id=dag_with_python_operator_v04, task_id=greet, execution_date=20230607T000000, start_date=20230608T203524, end_date=20230608T203524
[2023-06-08T20:35:24.268+0000] {standard_task_runner.py:109} ERROR - Failed to execute job 62 for task greet ('TaskInstance' object has no attribute 'xcoms_pull'; 2146)
[2023-06-08T20:35:24.303+0000] {local_task_job_runner.py:225} INFO - Task exited with return code 1
[2023-06-08T20:35:24.315+0000] {taskinstance.py:2651} INFO - 0 downstream tasks scheduled from follow-on schedule check
